WARNING:django.request:Not Found: /home/
DEBUG:MARKDOWN:Successfuly imported extension module "markdown.extensions.toc".
DEBUG:MARKDOWN:Successfully loaded extension "markdown.extensions.toc.TocExtension".
WARNING:django.request:Not Found: /favicon.ico
DEBUG:MARKDOWN:Successfuly imported extension module "markdown.extensions.toc".
DEBUG:MARKDOWN:Successfully loaded extension "markdown.extensions.toc.TocExtension".
DEBUG:MARKDOWN:Successfuly imported extension module "markdown.extensions.toc".
DEBUG:MARKDOWN:Successfully loaded extension "markdown.extensions.toc.TocExtension".
ERROR:django.request:Internal Server Error: /wordSearch
Traceback (most recent call last):
  File "C:\Python27\lib\site-packages\django\core\handlers\exception.py", line 41, in inner
    response = get_response(request)
  File "C:\Python27\lib\site-packages\django\utils\deprecation.py", line 138, in __call__
    response = self.process_request(request)
  File "C:\Python27\lib\site-packages\django\middleware\common.py", line 64, in process_request
    path = self.get_full_path_with_slash(request)
  File "C:\Python27\lib\site-packages\django\middleware\common.py", line 104, in get_full_path_with_slash
    'url': request.get_host() + new_path,
RuntimeError: You called this URL via POST, but the URL doesn't end in a slash and you have APPEND_SLASH set. Django can't redirect to the slash URL while maintaining POST data. Change your form to point to localhost:8000/wordSearch/ (note the trailing slash), or set APPEND_SLASH=False in your Django settings.
ERROR:django.request:Internal Server Error: /wordSearch
Traceback (most recent call last):
  File "C:\Python27\lib\site-packages\django\core\handlers\exception.py", line 41, in inner
    response = get_response(request)
  File "C:\Python27\lib\site-packages\django\utils\deprecation.py", line 138, in __call__
    response = self.process_request(request)
  File "C:\Python27\lib\site-packages\django\middleware\common.py", line 64, in process_request
    path = self.get_full_path_with_slash(request)
  File "C:\Python27\lib\site-packages\django\middleware\common.py", line 104, in get_full_path_with_slash
    'url': request.get_host() + new_path,
RuntimeError: You called this URL via POST, but the URL doesn't end in a slash and you have APPEND_SLASH set. Django can't redirect to the slash URL while maintaining POST data. Change your form to point to localhost:8000/wordSearch/ (note the trailing slash), or set APPEND_SLASH=False in your Django settings.
ERROR:django.request:Internal Server Error: /wordSearch
Traceback (most recent call last):
  File "C:\Python27\lib\site-packages\django\core\handlers\exception.py", line 41, in inner
    response = get_response(request)
  File "C:\Python27\lib\site-packages\django\utils\deprecation.py", line 138, in __call__
    response = self.process_request(request)
  File "C:\Python27\lib\site-packages\django\middleware\common.py", line 64, in process_request
    path = self.get_full_path_with_slash(request)
  File "C:\Python27\lib\site-packages\django\middleware\common.py", line 104, in get_full_path_with_slash
    'url': request.get_host() + new_path,
RuntimeError: You called this URL via POST, but the URL doesn't end in a slash and you have APPEND_SLASH set. Django can't redirect to the slash URL while maintaining POST data. Change your form to point to localhost:8000/wordSearch/ (note the trailing slash), or set APPEND_SLASH=False in your Django settings.
ERROR:django.request:Internal Server Error: /wordSearch
Traceback (most recent call last):
  File "C:\Python27\lib\site-packages\django\core\handlers\exception.py", line 41, in inner
    response = get_response(request)
  File "C:\Python27\lib\site-packages\django\utils\deprecation.py", line 138, in __call__
    response = self.process_request(request)
  File "C:\Python27\lib\site-packages\django\middleware\common.py", line 64, in process_request
    path = self.get_full_path_with_slash(request)
  File "C:\Python27\lib\site-packages\django\middleware\common.py", line 104, in get_full_path_with_slash
    'url': request.get_host() + new_path,
RuntimeError: You called this URL via POST, but the URL doesn't end in a slash and you have APPEND_SLASH set. Django can't redirect to the slash URL while maintaining POST data. Change your form to point to localhost:8000/wordSearch/ (note the trailing slash), or set APPEND_SLASH=False in your Django settings.
ERROR:django.request:Internal Server Error: /wordSearch
Traceback (most recent call last):
  File "C:\Python27\lib\site-packages\django\core\handlers\exception.py", line 41, in inner
    response = get_response(request)
  File "C:\Python27\lib\site-packages\django\core\handlers\base.py", line 187, in _get_response
    response = self.process_exception_by_middleware(e, request)
  File "C:\Python27\lib\site-packages\django\core\handlers\base.py", line 185, in _get_response
    response = wrapped_callback(request, *callback_args, **callback_kwargs)
  File "C:\Python27\lib\site-packages\django\views\decorators\csrf.py", line 58, in wrapped_view
    return view_func(*args, **kwargs)
  File "C:\Python27\lib\site-packages\django\views\generic\base.py", line 68, in view
    return self.dispatch(request, *args, **kwargs)
  File "C:\Python27\lib\site-packages\rest_framework\views.py", line 483, in dispatch
    response = self.handle_exception(exc)
  File "C:\Python27\lib\site-packages\rest_framework\views.py", line 443, in handle_exception
    self.raise_uncaught_exception(exc)
  File "C:\Python27\lib\site-packages\rest_framework\views.py", line 480, in dispatch
    response = handler(request, *args, **kwargs)
  File "C:\Python27\lib\site-packages\rest_framework\decorators.py", line 53, in handler
    return func(*args, **kwargs)
  File "C:\Users\pselvam101\Desktop\change\back_end\back_end\views.py", line 13, in word_search
    x=request.body()
TypeError: 'str' object is not callable
ERROR:django.request:Internal Server Error: /wordSearch
Traceback (most recent call last):
  File "C:\Python27\lib\site-packages\django\core\handlers\exception.py", line 41, in inner
    response = get_response(request)
  File "C:\Python27\lib\site-packages\django\core\handlers\base.py", line 187, in _get_response
    response = self.process_exception_by_middleware(e, request)
  File "C:\Python27\lib\site-packages\django\core\handlers\base.py", line 185, in _get_response
    response = wrapped_callback(request, *callback_args, **callback_kwargs)
  File "C:\Python27\lib\site-packages\django\views\decorators\csrf.py", line 58, in wrapped_view
    return view_func(*args, **kwargs)
  File "C:\Python27\lib\site-packages\django\views\generic\base.py", line 68, in view
    return self.dispatch(request, *args, **kwargs)
  File "C:\Python27\lib\site-packages\rest_framework\views.py", line 483, in dispatch
    response = self.handle_exception(exc)
  File "C:\Python27\lib\site-packages\rest_framework\views.py", line 443, in handle_exception
    self.raise_uncaught_exception(exc)
  File "C:\Python27\lib\site-packages\rest_framework\views.py", line 480, in dispatch
    response = handler(request, *args, **kwargs)
  File "C:\Python27\lib\site-packages\rest_framework\decorators.py", line 53, in handler
    return func(*args, **kwargs)
  File "C:\Users\pselvam101\Desktop\change\back_end\back_end\views.py", line 14, in word_search
    print received_request["data"]
KeyError: 'data'
ERROR:django.request:Internal Server Error: /wordSearch
Traceback (most recent call last):
  File "C:\Python27\lib\site-packages\django\core\handlers\exception.py", line 41, in inner
    response = get_response(request)
  File "C:\Python27\lib\site-packages\django\core\handlers\base.py", line 187, in _get_response
    response = self.process_exception_by_middleware(e, request)
  File "C:\Python27\lib\site-packages\django\core\handlers\base.py", line 185, in _get_response
    response = wrapped_callback(request, *callback_args, **callback_kwargs)
  File "C:\Python27\lib\site-packages\django\views\decorators\csrf.py", line 58, in wrapped_view
    return view_func(*args, **kwargs)
  File "C:\Python27\lib\site-packages\django\views\generic\base.py", line 68, in view
    return self.dispatch(request, *args, **kwargs)
  File "C:\Python27\lib\site-packages\rest_framework\views.py", line 483, in dispatch
    response = self.handle_exception(exc)
  File "C:\Python27\lib\site-packages\rest_framework\views.py", line 443, in handle_exception
    self.raise_uncaught_exception(exc)
  File "C:\Python27\lib\site-packages\rest_framework\views.py", line 480, in dispatch
    response = handler(request, *args, **kwargs)
  File "C:\Python27\lib\site-packages\rest_framework\decorators.py", line 53, in handler
    return func(*args, **kwargs)
  File "C:\Users\pselvam101\Desktop\change\back_end\back_end\views.py", line 19, in word_search
    if x.name.contains(userData):
AttributeError: 'unicode' object has no attribute 'contains'
ERROR:django.request:Internal Server Error: /wordSearch
Traceback (most recent call last):
  File "C:\Python27\lib\site-packages\django\core\handlers\exception.py", line 41, in inner
    response = get_response(request)
  File "C:\Python27\lib\site-packages\django\core\handlers\base.py", line 187, in _get_response
    response = self.process_exception_by_middleware(e, request)
  File "C:\Python27\lib\site-packages\django\core\handlers\base.py", line 185, in _get_response
    response = wrapped_callback(request, *callback_args, **callback_kwargs)
  File "C:\Python27\lib\site-packages\django\views\decorators\csrf.py", line 58, in wrapped_view
    return view_func(*args, **kwargs)
  File "C:\Python27\lib\site-packages\django\views\generic\base.py", line 68, in view
    return self.dispatch(request, *args, **kwargs)
  File "C:\Python27\lib\site-packages\rest_framework\views.py", line 483, in dispatch
    response = self.handle_exception(exc)
  File "C:\Python27\lib\site-packages\rest_framework\views.py", line 443, in handle_exception
    self.raise_uncaught_exception(exc)
  File "C:\Python27\lib\site-packages\rest_framework\views.py", line 480, in dispatch
    response = handler(request, *args, **kwargs)
  File "C:\Python27\lib\site-packages\rest_framework\decorators.py", line 53, in handler
    return func(*args, **kwargs)
  File "C:\Users\pselvam101\Desktop\change\back_end\back_end\views.py", line 19, in word_search
    if str(x.name).contains(userData):
AttributeError: 'str' object has no attribute 'contains'
ERROR:django.request:Internal Server Error: /wordSearch
Traceback (most recent call last):
  File "C:\Python27\lib\site-packages\django\core\handlers\exception.py", line 41, in inner
    response = get_response(request)
  File "C:\Python27\lib\site-packages\django\core\handlers\base.py", line 187, in _get_response
    response = self.process_exception_by_middleware(e, request)
  File "C:\Python27\lib\site-packages\django\core\handlers\base.py", line 185, in _get_response
    response = wrapped_callback(request, *callback_args, **callback_kwargs)
  File "C:\Python27\lib\site-packages\django\views\decorators\csrf.py", line 58, in wrapped_view
    return view_func(*args, **kwargs)
  File "C:\Python27\lib\site-packages\django\views\generic\base.py", line 68, in view
    return self.dispatch(request, *args, **kwargs)
  File "C:\Python27\lib\site-packages\rest_framework\views.py", line 483, in dispatch
    response = self.handle_exception(exc)
  File "C:\Python27\lib\site-packages\rest_framework\views.py", line 443, in handle_exception
    self.raise_uncaught_exception(exc)
  File "C:\Python27\lib\site-packages\rest_framework\views.py", line 480, in dispatch
    response = handler(request, *args, **kwargs)
  File "C:\Python27\lib\site-packages\rest_framework\decorators.py", line 53, in handler
    return func(*args, **kwargs)
  File "C:\Users\pselvam101\Desktop\change\back_end\back_end\views.py", line 19, in word_search
    if (str(x.name)).contains(userData):
AttributeError: 'str' object has no attribute 'contains'
ERROR:django.request:Internal Server Error: /wordSearch
Traceback (most recent call last):
  File "C:\Python27\lib\site-packages\django\core\handlers\exception.py", line 41, in inner
    response = get_response(request)
  File "C:\Python27\lib\site-packages\django\core\handlers\base.py", line 187, in _get_response
    response = self.process_exception_by_middleware(e, request)
  File "C:\Python27\lib\site-packages\django\core\handlers\base.py", line 185, in _get_response
    response = wrapped_callback(request, *callback_args, **callback_kwargs)
  File "C:\Python27\lib\site-packages\django\views\decorators\csrf.py", line 58, in wrapped_view
    return view_func(*args, **kwargs)
  File "C:\Python27\lib\site-packages\django\views\generic\base.py", line 68, in view
    return self.dispatch(request, *args, **kwargs)
  File "C:\Python27\lib\site-packages\rest_framework\views.py", line 483, in dispatch
    response = self.handle_exception(exc)
  File "C:\Python27\lib\site-packages\rest_framework\views.py", line 443, in handle_exception
    self.raise_uncaught_exception(exc)
  File "C:\Python27\lib\site-packages\rest_framework\views.py", line 480, in dispatch
    response = handler(request, *args, **kwargs)
  File "C:\Python27\lib\site-packages\rest_framework\decorators.py", line 53, in handler
    return func(*args, **kwargs)
  File "C:\Users\pselvam101\Desktop\change\back_end\back_end\views.py", line 18, in word_search
    temp=Words(name__startswith=userData)
  File "C:\Python27\lib\site-packages\django\db\models\base.py", line 573, in __init__
    raise TypeError("'%s' is an invalid keyword argument for this function" % list(kwargs)[0])
TypeError: 'name__startswith' is an invalid keyword argument for this function
ERROR:django.request:Internal Server Error: /wordSearch
Traceback (most recent call last):
  File "C:\Python27\lib\site-packages\django\core\handlers\exception.py", line 41, in inner
    response = get_response(request)
  File "C:\Python27\lib\site-packages\django\core\handlers\base.py", line 187, in _get_response
    response = self.process_exception_by_middleware(e, request)
  File "C:\Python27\lib\site-packages\django\core\handlers\base.py", line 185, in _get_response
    response = wrapped_callback(request, *callback_args, **callback_kwargs)
  File "C:\Python27\lib\site-packages\django\views\decorators\csrf.py", line 58, in wrapped_view
    return view_func(*args, **kwargs)
  File "C:\Python27\lib\site-packages\django\views\generic\base.py", line 68, in view
    return self.dispatch(request, *args, **kwargs)
  File "C:\Python27\lib\site-packages\rest_framework\views.py", line 483, in dispatch
    response = self.handle_exception(exc)
  File "C:\Python27\lib\site-packages\rest_framework\views.py", line 443, in handle_exception
    self.raise_uncaught_exception(exc)
  File "C:\Python27\lib\site-packages\rest_framework\views.py", line 480, in dispatch
    response = handler(request, *args, **kwargs)
  File "C:\Python27\lib\site-packages\rest_framework\decorators.py", line 53, in handler
    return func(*args, **kwargs)
  File "C:\Users\pselvam101\Desktop\change\back_end\back_end\views.py", line 18, in word_search
    temp=Words.objects.filter(Q(name__startswith=userData))
NameError: global name 'Q' is not defined
ERROR:django.request:Internal Server Error: /wordSearch
Traceback (most recent call last):
  File "C:\Python27\lib\site-packages\django\core\handlers\exception.py", line 41, in inner
    response = get_response(request)
  File "C:\Python27\lib\site-packages\django\core\handlers\base.py", line 187, in _get_response
    response = self.process_exception_by_middleware(e, request)
  File "C:\Python27\lib\site-packages\django\core\handlers\base.py", line 185, in _get_response
    response = wrapped_callback(request, *callback_args, **callback_kwargs)
  File "C:\Python27\lib\site-packages\django\views\decorators\csrf.py", line 58, in wrapped_view
    return view_func(*args, **kwargs)
  File "C:\Python27\lib\site-packages\django\views\generic\base.py", line 68, in view
    return self.dispatch(request, *args, **kwargs)
  File "C:\Python27\lib\site-packages\rest_framework\views.py", line 483, in dispatch
    response = self.handle_exception(exc)
  File "C:\Python27\lib\site-packages\rest_framework\views.py", line 443, in handle_exception
    self.raise_uncaught_exception(exc)
  File "C:\Python27\lib\site-packages\rest_framework\views.py", line 480, in dispatch
    response = handler(request, *args, **kwargs)
  File "C:\Python27\lib\site-packages\rest_framework\decorators.py", line 53, in handler
    return func(*args, **kwargs)
  File "C:\Users\pselvam101\Desktop\change\back_end\back_end\views.py", line 22, in word_search
    if len(temp)==0:
NameError: global name 'temp' is not defined
ERROR:django.request:Internal Server Error: /wordSearch
Traceback (most recent call last):
  File "C:\Python27\lib\site-packages\django\core\handlers\exception.py", line 41, in inner
    response = get_response(request)
  File "C:\Python27\lib\site-packages\django\core\handlers\base.py", line 187, in _get_response
    response = self.process_exception_by_middleware(e, request)
  File "C:\Python27\lib\site-packages\django\core\handlers\base.py", line 185, in _get_response
    response = wrapped_callback(request, *callback_args, **callback_kwargs)
  File "C:\Python27\lib\site-packages\django\views\decorators\csrf.py", line 58, in wrapped_view
    return view_func(*args, **kwargs)
  File "C:\Python27\lib\site-packages\django\views\generic\base.py", line 68, in view
    return self.dispatch(request, *args, **kwargs)
  File "C:\Python27\lib\site-packages\rest_framework\views.py", line 483, in dispatch
    response = self.handle_exception(exc)
  File "C:\Python27\lib\site-packages\rest_framework\views.py", line 443, in handle_exception
    self.raise_uncaught_exception(exc)
  File "C:\Python27\lib\site-packages\rest_framework\views.py", line 480, in dispatch
    response = handler(request, *args, **kwargs)
  File "C:\Python27\lib\site-packages\rest_framework\decorators.py", line 53, in handler
    return func(*args, **kwargs)
  File "C:\Users\pselvam101\Desktop\change\back_end\back_end\views.py", line 22, in word_search
    if len(temp)==0:
NameError: global name 'temp' is not defined
ERROR:django.request:Internal Server Error: /wordSearch
Traceback (most recent call last):
  File "C:\Python27\lib\site-packages\django\core\handlers\exception.py", line 41, in inner
    response = get_response(request)
  File "C:\Python27\lib\site-packages\django\core\handlers\base.py", line 187, in _get_response
    response = self.process_exception_by_middleware(e, request)
  File "C:\Python27\lib\site-packages\django\core\handlers\base.py", line 185, in _get_response
    response = wrapped_callback(request, *callback_args, **callback_kwargs)
  File "C:\Python27\lib\site-packages\django\views\decorators\csrf.py", line 58, in wrapped_view
    return view_func(*args, **kwargs)
  File "C:\Python27\lib\site-packages\django\views\generic\base.py", line 68, in view
    return self.dispatch(request, *args, **kwargs)
  File "C:\Python27\lib\site-packages\rest_framework\views.py", line 483, in dispatch
    response = self.handle_exception(exc)
  File "C:\Python27\lib\site-packages\rest_framework\views.py", line 443, in handle_exception
    self.raise_uncaught_exception(exc)
  File "C:\Python27\lib\site-packages\rest_framework\views.py", line 480, in dispatch
    response = handler(request, *args, **kwargs)
  File "C:\Python27\lib\site-packages\rest_framework\decorators.py", line 53, in handler
    return func(*args, **kwargs)
  File "C:\Users\pselvam101\Desktop\change\back_end\back_end\views.py", line 36, in word_search
    for key,value in dataDictionary.values():
ValueError: too many values to unpack
